crates/engine-core/tests/data/output_file_rust.csv
A, 1, 1
B, B, 10, 100
A, 1, 2
B, S, 12, 100
A, 2, 101
A, 2, 102
B, S, 11, 100
A, 1, 3
T, 1, 3, 2, 102, 11, 100
B, S, 12, 100
A, 2, 103
T, 1, 1, 2, 103, 10, 100
B, B, 9, 100
A, 1, 4
B, B, 10, 100
A, 2, 104
B, S, 11, 100
C, 1, 4
C, 2, 101
C, 2, 104
C, 1, 2
B, B, -, -
B, S, -, -
A, 1, 1
B, B, 10, 100
A, 1, 2
B, S, 12, 100
A, 2, 102
B, S, 11, 100
A, 2, 103
T, 1, 1, 2, 103, 10, 100
B, B, -, -
A, 1, 3
B, B, 10, 100
C, 1, 3
C, 2, 102
C, 1, 2
B, B, -, -
B, S, -, -
A, 1, 1
B, B, 10, 100
A, 2, 101
A, 2, 102
B, S, 11, 100
A, 1, 2
T, 1, 2, 2, 102, 11, 100
B, S, -, -
A, 2, 103
B, S, 11, 100
C, 1, 1
C, 2, 101
C, 2, 103
B, B, -, -
B, S, -, -
A, 1, 1
B, B, 10, 100
A, 1, 2
B, S, 12, 100
A, 2, 101
A, 2, 102
B, S, 11, 100
A, 2, 103
T, 1, 1, 2, 103, 10, 100
B, B, 9, 100
C, 2, 101
C, 2, 102
C, 1, 2
B, B, -, -
B, S, -, -
A, 1, 1
B, B, 10, 100
A, 1, 2
B, S, 12, 100
A, 2, 101
A, 2, 102
B, S, 11, 100
A, 1, 103
T, 1, 103, 2, 102, 11, 100
B, S, 12, 100
C, 1, 1
C, 2, 101
C, 1, 2
B, B, -, -
B, S, -, -
A, 1, 1
B, B, 10, 100
A, 1, 2
B, S, 12, 100
A, 2, 101
A, 2, 102
B, S, 11, 100
A, 2, 103
T, 1, 1, 2, 103, 10, 100
B, B, 9, 100
C, 2, 101
C, 2, 102
C, 1, 2
B, B, -, -
B, S, -, -
A, 1, 1
B, B, 10, 100
A, 1, 2
B, S, 12, 100
A, 2, 101
A, 2, 102
B, S, 11, 100
A, 1, 3
T, 1, 3, 2, 102, 11, 100
B, S, 12, 100
C, 1, 1
C, 2, 101
C, 1, 2
B, B, -, -
B, S, -, -
A, 1, 1
B, B, 10, 100
A, 1, 2
B, S, 16, 100
A, 2, 101
A, 2, 102
B, S, 15, 100
A, 2, 103
B, B, 11, 100
A, 1, 3
B, S, 14, 100
C, 2, 103
C, 1, 1
C, 2, 101
C, 1, 3
C, 2, 102
C, 1, 2
B, B, -, -
B, S, -, -
A, 1, 1
B, B, 10, 100
A, 1, 2
B, S, 12, 100
A, 2, 101
A, 2, 102
B, S, 11, 100
A, 2, 103
T, 1, 1, 2, 103, 10, 20
B, B, 10, 80
C, 1, 1
C, 2, 101
C, 2, 102
C, 1, 2
B, B, -, -
B, S, -, -
A, 1, 1
B, B, 10, 100
A, 1, 2
B, S, 12, 100
A, 2, 101
A, 2, 102
B, S, 11, 100
A, 1, 3
T, 1, 3, 2, 102, 11, 20
B, S, 11, 80
C, 1, 1
C, 2, 101
C, 2, 102
C, 1, 2
B, B, -, -
B, S, -, -
A, 1, 1
B, B, 10, 100
A, 1, 2
B, S, 12, 100
A, 2, 101
A, 2, 102
B, S, 11, 100
A, 2, 103
T, 1, 1, 2, 103, 10, 20
B, B, 10, 80
C, 1, 1
C, 2, 101
C, 2, 102
C, 1, 2
B, B, -, -
B, S, -, -
A, 1, 1
B, B, 10, 100
A, 1, 2
B, S, 12, 100
A, 2, 101
A, 2, 102
B, S, 11, 100
A, 1, 3
T, 1, 3, 2, 102, 11, 20
B, S, 11, 80
C, 1, 1
C, 2, 101
C, 2, 102
C, 1, 2
B, B, -, -
B, S, -, -
A, 1, 1
B, B, 10, 100
A, 1, 2
B, S, 12, 100
A, 2, 101
A, 2, 102
B, S, 11, 100
A, 2, 103
B, B, 10, 150
A, 1, 3
B, S, 11, 150
A, 1, 4
T, 1, 4, 2, 102, 11, 100
B, S, 11, 50
A, 2, 104
T, 1, 1, 2, 104, 10, 100
B, B, 10, 50
C, 2, 103
C, 2, 101
C, 1, 3
C, 1, 2
B, B, -, -
B, S, -, -
A, 1, 1
B, B, 10, 100
A, 1, 2
B, S, 12, 100
A, 2, 101
A, 2, 102
B, S, 11, 100
C, 1, 1
B, B, 9, 100
C, 2, 102
B, S, 12, 100
C, 2, 101
C, 1, 2
B, B, -, -
B, S, -, -
A, 1, 1
B, B, 10, 100
A, 1, 2
B, S, 12, 100
A, 2, 101
A, 2, 102
B, S, 11, 100
C, 1, 2
C, 2, 101
C, 1, 1
C, 2, 102
B, B, -, -
B, S, -, -
A, 1, 1
B, B, 10, 100
A, 1, 2
B, S, 12, 100
A, 2, 101
A, 2, 102
B, S, 11, 100
C, 1, 1
B, B, 9, 100
C, 2, 101
B, B, -, -
C, 2, 102
C, 1, 2
B, S, -, -
